import { NextFunction, Request, RequestHandler, Response } from 'express';
import { StudentServices } from './student.service';
import httpStatus from 'http-status';
import sendResponse from '../../utils/sendResponse';

// this higher order function will receive an async func(which type is RequestHandler) as parameter and if there is an error it will handle it in the catch block otherwise it will resolve the promise. and we have to return the result inside a function
const catchAsync = (fn: RequestHandler) => {
  return (req: Request, res: Response, next: NextFunction) => {
    Promise.resolve(fn(req, res, next)).catch((err) => next(err));
  };
};

const getAllStudents = catchAsync(async (req, res, next) => {
  const result = await StudentServices.getAllStudentsFromDB();

  sendResponse(res, {
    statusCode: httpStatus.OK,
    success: true,
    message: 'Students are retrieved successfully',
    data: result,
  });
});

const getSingleStudent = catchAsync(async (req, res, next) => {
  const { studentId } = req.params;

  const result = await StudentServices.getSingleStudentFromDB(studentId);

  sendResponse(res, {
    statusCode: httpStatus.OK,
    success: true,
    message: 'Students is retrieved successfully',
    data: result,
  });
});

const deleteStudent = catchAsync(async (req, res, next) => {
  const { studentId } = req.params;

  const result = await StudentServices.deleteStudentFromDB(studentId);

  sendResponse(res, {
    statusCode: httpStatus.OK,
    success: true,
    message: 'Students is deleted successfully',
    data: result,
  });
});

export const StudentControllers = {
  getAllStudents,
  getSingleStudent,
  deleteStudent,
};
